Workbook

Sheet Guide
B2: Week 7 marking workbook: Trovra support desk simulation
B3: FAKE DATA. Every record in this file was generated by a script. Use it to test the workflow, not to mark learners.
B5: Certificate in Customer Service and Virtual Assistance. Week 7: difficult customers and conflict resolution. Checkpoint: role-play rubric.
B7: 1. Choose the trial | C7: On the Learners sheet, type 1, 2 or 3 in the yellow Selected trial cell for each learner. Nothing is chosen for you: the workbook does not pick the latest or the highest-scoring trial. Only submitted trials can be marked.
B8: 2. Read the evidence | C8: Case sheets list every submitted trial. Rows for the selected trial turn green and show SELECTED. Filter column D on SELECTED to see only those. Read the Transcript and Note columns. The Transcripts sheet shows the same transcripts one message per row.
B9: 3. Score | C9: Type scores into the yellow cells. Reply criteria R1 to R10: 0 (not shown), 1 (partly shown), 2 (clearly shown). Note criteria N1 to N5: 0 or 1. Totals calculate by themselves.
B10: 4. Check totals | C10: The Learners sheet adds the four case totals into a mark out of 100 for the selected trial. The Trials sheet shows a total for every trial.
B11: Engine evidence | C11: Flags, Signals and Heat history come from the rule engine. They point you to things worth checking, such as an overpromise, a boundary, or a missed window. They do not award marks and they can miss valid phrasings. Score from the transcript.
B12: Transcripts are untouched | C12: Learner messages are copied exactly as stored. Do not edit them. Times are West Africa Time (WAT).
B13: Calibration | C13: Before marking the cohort, two people (or you twice, a day apart) score the same two sample transcripts. Record the totals on the Calibration sheet and discuss any criterion where scores differ by more than 1 mark.
B14: Marks | C14: Each case: 20 marks for replies (10 criteria x 2) plus 5 marks for the service recovery note. Four cases: 100 marks per trial.
B15: Cell colours | C15: Yellow fill with blue text: you type here. Green row: selected trial. Everything else is locked in your head only: the sheets are not protected, so avoid typing over them.
B17: Source file | C17: sample/fake_trials.csv: 6 trial(s), 5 submitted, 5 learner(s).

Sheet Learners
A1: Learners and marks
A2: Choose the trial to mark in the yellow column. Marks come from the case sheets for that trial. A blank selection means that learner is not yet chosen.
A5: Learner | B5: Email | C5: Trials submitted | D5: Selected trial | E5: Selection check | F5: A replies | G5: A note | H5: B replies | I5: B note | J5: C replies | K5: C note | L5: D replies | M5: D note | N5: Total (of 100) | O5: Entries filled (of 60)
A6: Chidi Eze | B6: chidi.eze@example.test | C6: 1, 2 | E6: =IF($D6="","Not selected",IF(COUNTIFS(Trials!$B$6:$B$500,$B6,Trials!$C$6:$C$500,$D6,Trials!$E$6:$E$500,"submitted")=1,"OK","Not a submitted trial")) -> Not selected | F6: =IF($D6="","",SUMIFS('Case A'!$X$6:$X$10,'Case A'!$B$6:$B$10,$B6,'Case A'!$C$6:$C$10,$D6)) | G6: =IF($D6="","",SUMIFS('Case A'!$AD$6:$AD$10,'Case A'!$B$6:$B$10,$B6,'Case A'!$C$6:$C$10,$D6)) | H6: =IF($D6="","",SUMIFS('Case B'!$X$6:$X$10,'Case B'!$B$6:$B$10,$B6,'Case B'!$C$6:$C$10,$D6)) | I6: =IF($D6="","",SUMIFS('Case B'!$AD$6:$AD$10,'Case B'!$B$6:$B$10,$B6,'Case B'!$C$6:$C$10,$D6)) | J6: =IF($D6="","",SUMIFS('Case C'!$X$6:$X$10,'Case C'!$B$6:$B$10,$B6,'Case C'!$C$6:$C$10,$D6)) | K6: =IF($D6="","",SUMIFS('Case C'!$AD$6:$AD$10,'Case C'!$B$6:$B$10,$B6,'Case C'!$C$6:$C$10,$D6)) | L6: =IF($D6="","",SUMIFS('Case D'!$X$6:$X$10,'Case D'!$B$6:$B$10,$B6,'Case D'!$C$6:$C$10,$D6)) | M6: =IF($D6="","",SUMIFS('Case D'!$AD$6:$AD$10,'Case D'!$B$6:$B$10,$B6,'Case D'!$C$6:$C$10,$D6)) | N6: =IF($D6="","",SUM(F6:M6)) | O6: =IF($D6="","",SUMIFS('Case A'!$AF$6:$AF$10,'Case A'!$B$6:$B$10,$B6,'Case A'!$C$6:$C$10,$D6)+SUMIFS('Case B'!$AF$6:$AF$10,'Case B'!$B$6:$B$10,$B6,'Case B'!$C$6:$C$10,$D6)+SUMIFS('Case C'!$AF$6:$AF$10,'Case C'!$B$6:$B$10,$B6,'Case C'!$C$6:$C$10,$D6)+SUMIFS('Case D'!$AF$6:$AF$10,'Case D'!$B$6:$B$10,$B6,'Case D'!$C$6:$C$10,$D6))
A7: Funmi Bello | B7: funmi.bello@example.test | C7: 1 | E7: =IF($D7="","Not selected",IF(COUNTIFS(Trials!$B$6:$B$500,$B7,Trials!$C$6:$C$500,$D7,Trials!$E$6:$E$500,"submitted")=1,"OK","Not a submitted trial")) -> Not selected | F7: =IF($D7="","",SUMIFS('Case A'!$X$6:$X$10,'Case A'!$B$6:$B$10,$B7,'Case A'!$C$6:$C$10,$D7)) | G7: =IF($D7="","",SUMIFS('Case A'!$AD$6:$AD$10,'Case A'!$B$6:$B$10,$B7,'Case A'!$C$6:$C$10,$D7)) | H7: =IF($D7="","",SUMIFS('Case B'!$X$6:$X$10,'Case B'!$B$6:$B$10,$B7,'Case B'!$C$6:$C$10,$D7)) | I7: =IF($D7="","",SUMIFS('Case B'!$AD$6:$AD$10,'Case B'!$B$6:$B$10,$B7,'Case B'!$C$6:$C$10,$D7)) | J7: =IF($D7="","",SUMIFS('Case C'!$X$6:$X$10,'Case C'!$B$6:$B$10,$B7,'Case C'!$C$6:$C$10,$D7)) | K7: =IF($D7="","",SUMIFS('Case C'!$AD$6:$AD$10,'Case C'!$B$6:$B$10,$B7,'Case C'!$C$6:$C$10,$D7)) | L7: =IF($D7="","",SUMIFS('Case D'!$X$6:$X$10,'Case D'!$B$6:$B$10,$B7,'Case D'!$C$6:$C$10,$D7)) | M7: =IF($D7="","",SUMIFS('Case D'!$AD$6:$AD$10,'Case D'!$B$6:$B$10,$B7,'Case D'!$C$6:$C$10,$D7)) | N7: =IF($D7="","",SUM(F7:M7)) | O7: =IF($D7="","",SUMIFS('Case A'!$AF$6:$AF$10,'Case A'!$B$6:$B$10,$B7,'Case A'!$C$6:$C$10,$D7)+SUMIFS('Case B'!$AF$6:$AF$10,'Case B'!$B$6:$B$10,$B7,'Case B'!$C$6:$C$10,$D7)+SUMIFS('Case C'!$AF$6:$AF$10,'Case C'!$B$6:$B$10,$B7,'Case C'!$C$6:$C$10,$D7)+SUMIFS('Case D'!$AF$6:$AF$10,'Case D'!$B$6:$B$10,$B7,'Case D'!$C$6:$C$10,$D7))
A8: Garba Musa | B8: garba.musa@example.test | C8: 1 | E8: =IF($D8="","Not selected",IF(COUNTIFS(Trials!$B$6:$B$500,$B8,Trials!$C$6:$C$500,$D8,Trials!$E$6:$E$500,"submitted")=1,"OK","Not a submitted trial")) -> Not selected | F8: =IF($D8="","",SUMIFS('Case A'!$X$6:$X$10,'Case A'!$B$6:$B$10,$B8,'Case A'!$C$6:$C$10,$D8)) | G8: =IF($D8="","",SUMIFS('Case A'!$AD$6:$AD$10,'Case A'!$B$6:$B$10,$B8,'Case A'!$C$6:$C$10,$D8)) | H8: =IF($D8="","",SUMIFS('Case B'!$X$6:$X$10,'Case B'!$B$6:$B$10,$B8,'Case B'!$C$6:$C$10,$D8)) | I8: =IF($D8="","",SUMIFS('Case B'!$AD$6:$AD$10,'Case B'!$B$6:$B$10,$B8,'Case B'!$C$6:$C$10,$D8)) | J8: =IF($D8="","",SUMIFS('Case C'!$X$6:$X$10,'Case C'!$B$6:$B$10,$B8,'Case C'!$C$6:$C$10,$D8)) | K8: =IF($D8="","",SUMIFS('Case C'!$AD$6:$AD$10,'Case C'!$B$6:$B$10,$B8,'Case C'!$C$6:$C$10,$D8)) | L8: =IF($D8="","",SUMIFS('Case D'!$X$6:$X$10,'Case D'!$B$6:$B$10,$B8,'Case D'!$C$6:$C$10,$D8)) | M8: =IF($D8="","",SUMIFS('Case D'!$AD$6:$AD$10,'Case D'!$B$6:$B$10,$B8,'Case D'!$C$6:$C$10,$D8)) | N8: =IF($D8="","",SUM(F8:M8)) | O8: =IF($D8="","",SUMIFS('Case A'!$AF$6:$AF$10,'Case A'!$B$6:$B$10,$B8,'Case A'!$C$6:$C$10,$D8)+SUMIFS('Case B'!$AF$6:$AF$10,'Case B'!$B$6:$B$10,$B8,'Case B'!$C$6:$C$10,$D8)+SUMIFS('Case C'!$AF$6:$AF$10,'Case C'!$B$6:$B$10,$B8,'Case C'!$C$6:$C$10,$D8)+SUMIFS('Case D'!$AF$6:$AF$10,'Case D'!$B$6:$B$10,$B8,'Case D'!$C$6:$C$10,$D8))
A9: Halima Yusuf | B9: halima.yusuf@example.test | C9: 1 | E9: =IF($D9="","Not selected",IF(COUNTIFS(Trials!$B$6:$B$500,$B9,Trials!$C$6:$C$500,$D9,Trials!$E$6:$E$500,"submitted")=1,"OK","Not a submitted trial")) -> Not selected | F9: =IF($D9="","",SUMIFS('Case A'!$X$6:$X$10,'Case A'!$B$6:$B$10,$B9,'Case A'!$C$6:$C$10,$D9)) | G9: =IF($D9="","",SUMIFS('Case A'!$AD$6:$AD$10,'Case A'!$B$6:$B$10,$B9,'Case A'!$C$6:$C$10,$D9)) | H9: =IF($D9="","",SUMIFS('Case B'!$X$6:$X$10,'Case B'!$B$6:$B$10,$B9,'Case B'!$C$6:$C$10,$D9)) | I9: =IF($D9="","",SUMIFS('Case B'!$AD$6:$AD$10,'Case B'!$B$6:$B$10,$B9,'Case B'!$C$6:$C$10,$D9)) | J9: =IF($D9="","",SUMIFS('Case C'!$X$6:$X$10,'Case C'!$B$6:$B$10,$B9,'Case C'!$C$6:$C$10,$D9)) | K9: =IF($D9="","",SUMIFS('Case C'!$AD$6:$AD$10,'Case C'!$B$6:$B$10,$B9,'Case C'!$C$6:$C$10,$D9)) | L9: =IF($D9="","",SUMIFS('Case D'!$X$6:$X$10,'Case D'!$B$6:$B$10,$B9,'Case D'!$C$6:$C$10,$D9)) | M9: =IF($D9="","",SUMIFS('Case D'!$AD$6:$AD$10,'Case D'!$B$6:$B$10,$B9,'Case D'!$C$6:$C$10,$D9)) | N9: =IF($D9="","",SUM(F9:M9)) | O9: =IF($D9="","",SUMIFS('Case A'!$AF$6:$AF$10,'Case A'!$B$6:$B$10,$B9,'Case A'!$C$6:$C$10,$D9)+SUMIFS('Case B'!$AF$6:$AF$10,'Case B'!$B$6:$B$10,$B9,'Case B'!$C$6:$C$10,$D9)+SUMIFS('Case C'!$AF$6:$AF$10,'Case C'!$B$6:$B$10,$B9,'Case C'!$C$6:$C$10,$D9)+SUMIFS('Case D'!$AF$6:$AF$10,'Case D'!$B$6:$B$10,$B9,'Case D'!$C$6:$C$10,$D9))
A10: Ifeanyi Obi | B10: ifeanyi.obi@example.test | C10: none | E10: =IF($D10="","Not selected",IF(COUNTIFS(Trials!$B$6:$B$500,$B10,Trials!$C$6:$C$500,$D10,Trials!$E$6:$E$500,"submitted")=1,"OK","Not a submitted trial")) -> Not selected | F10: =IF($D10="","",SUMIFS('Case A'!$X$6:$X$10,'Case A'!$B$6:$B$10,$B10,'Case A'!$C$6:$C$10,$D10)) | G10: =IF($D10="","",SUMIFS('Case A'!$AD$6:$AD$10,'Case A'!$B$6:$B$10,$B10,'Case A'!$C$6:$C$10,$D10)) | H10: =IF($D10="","",SUMIFS('Case B'!$X$6:$X$10,'Case B'!$B$6:$B$10,$B10,'Case B'!$C$6:$C$10,$D10)) | I10: =IF($D10="","",SUMIFS('Case B'!$AD$6:$AD$10,'Case B'!$B$6:$B$10,$B10,'Case B'!$C$6:$C$10,$D10)) | J10: =IF($D10="","",SUMIFS('Case C'!$X$6:$X$10,'Case C'!$B$6:$B$10,$B10,'Case C'!$C$6:$C$10,$D10)) | K10: =IF($D10="","",SUMIFS('Case C'!$AD$6:$AD$10,'Case C'!$B$6:$B$10,$B10,'Case C'!$C$6:$C$10,$D10)) | L10: =IF($D10="","",SUMIFS('Case D'!$X$6:$X$10,'Case D'!$B$6:$B$10,$B10,'Case D'!$C$6:$C$10,$D10)) | M10: =IF($D10="","",SUMIFS('Case D'!$AD$6:$AD$10,'Case D'!$B$6:$B$10,$B10,'Case D'!$C$6:$C$10,$D10)) | N10: =IF($D10="","",SUM(F10:M10)) | O10: =IF($D10="","",SUMIFS('Case A'!$AF$6:$AF$10,'Case A'!$B$6:$B$10,$B10,'Case A'!$C$6:$C$10,$D10)+SUMIFS('Case B'!$AF$6:$AF$10,'Case B'!$B$6:$B$10,$B10,'Case B'!$C$6:$C$10,$D10)+SUMIFS('Case C'!$AF$6:$AF$10,'Case C'!$B$6:$B$10,$B10,'Case C'!$C$6:$C$10,$D10)+SUMIFS('Case D'!$AF$6:$AF$10,'Case D'!$B$6:$B$10,$B10,'Case D'!$C$6:$C$10,$D10))

Sheet Trials
A1: All trials
A2: Every trial that exists, submitted or open. Open trials cannot be marked. Totals show the marks entered so far for each trial.
A5: Learner | B5: Email | C5: Trial | D5: Fact set | E5: Status | F5: Shift started (WAT) | G5: Submitted (WAT) | H5: Resets | I5: Offline gaps | J5: Selected for marking? | K5: Total entered (of 100)
A6: Chidi Eze | B6: chidi.eze@example.test | C6: 1 | D6: 1 | E6: submitted | F6: Mon, 26 Oct 2026, 9:00am WAT | G6: Mon, 26 Oct 2026, 9:24am WAT | H6: 0 | J6: =IF(IFERROR(INDEX(Learners!$D$6:$D$500,MATCH($B6,Learners!$B$6:$B$500,0)),"")=$C6,"SELECTED","") | K6: =SUMIFS('Case A'!$AE$6:$AE$10,'Case A'!$B$6:$B$10,$B6,'Case A'!$C$6:$C$10,$C6)+SUMIFS('Case B'!$AE$6:$AE$10,'Case B'!$B$6:$B$10,$B6,'Case B'!$C$6:$C$10,$C6)+SUMIFS('Case C'!$AE$6:$AE$10,'Case C'!$B$6:$B$10,$B6,'Case C'!$C$6:$C$10,$C6)+SUMIFS('Case D'!$AE$6:$AE$10,'Case D'!$B$6:$B$10,$B6,'Case D'!$C$6:$C$10,$C6) -> 0
A7: Chidi Eze | B7: chidi.eze@example.test | C7: 2 | D7: 2 | E7: submitted | F7: Mon, 26 Oct 2026, 10:24am WAT | G7: Mon, 26 Oct 2026, 10:36am WAT | H7: 0 | J7: =IF(IFERROR(INDEX(Learners!$D$6:$D$500,MATCH($B7,Learners!$B$6:$B$500,0)),"")=$C7,"SELECTED","") | K7: =SUMIFS('Case A'!$AE$6:$AE$10,'Case A'!$B$6:$B$10,$B7,'Case A'!$C$6:$C$10,$C7)+SUMIFS('Case B'!$AE$6:$AE$10,'Case B'!$B$6:$B$10,$B7,'Case B'!$C$6:$C$10,$C7)+SUMIFS('Case C'!$AE$6:$AE$10,'Case C'!$B$6:$B$10,$B7,'Case C'!$C$6:$C$10,$C7)+SUMIFS('Case D'!$AE$6:$AE$10,'Case D'!$B$6:$B$10,$B7,'Case D'!$C$6:$C$10,$C7) -> 0
A8: Funmi Bello | B8: funmi.bello@example.test | C8: 1 | D8: 1 | E8: submitted | F8: Mon, 26 Oct 2026, 11:06am WAT | G8: Mon, 26 Oct 2026, 11:31am WAT | H8: 0 | J8: =IF(IFERROR(INDEX(Learners!$D$6:$D$500,MATCH($B8,Learners!$B$6:$B$500,0)),"")=$C8,"SELECTED","") | K8: =SUMIFS('Case A'!$AE$6:$AE$10,'Case A'!$B$6:$B$10,$B8,'Case A'!$C$6:$C$10,$C8)+SUMIFS('Case B'!$AE$6:$AE$10,'Case B'!$B$6:$B$10,$B8,'Case B'!$C$6:$C$10,$C8)+SUMIFS('Case C'!$AE$6:$AE$10,'Case C'!$B$6:$B$10,$B8,'Case C'!$C$6:$C$10,$C8)+SUMIFS('Case D'!$AE$6:$AE$10,'Case D'!$B$6:$B$10,$B8,'Case D'!$C$6:$C$10,$C8) -> 0
A9: Garba Musa | B9: garba.musa@example.test | C9: 1 | D9: 1 | E9: submitted | F9: Mon, 26 Oct 2026, 12:01pm WAT | G9: Mon, 26 Oct 2026, 12:20pm WAT | H9: 0 | J9: =IF(IFERROR(INDEX(Learners!$D$6:$D$500,MATCH($B9,Learners!$B$6:$B$500,0)),"")=$C9,"SELECTED","") | K9: =SUMIFS('Case A'!$AE$6:$AE$10,'Case A'!$B$6:$B$10,$B9,'Case A'!$C$6:$C$10,$C9)+SUMIFS('Case B'!$AE$6:$AE$10,'Case B'!$B$6:$B$10,$B9,'Case B'!$C$6:$C$10,$C9)+SUMIFS('Case C'!$AE$6:$AE$10,'Case C'!$B$6:$B$10,$B9,'Case C'!$C$6:$C$10,$C9)+SUMIFS('Case D'!$AE$6:$AE$10,'Case D'!$B$6:$B$10,$B9,'Case D'!$C$6:$C$10,$C9) -> 0
A10: Halima Yusuf | B10: halima.yusuf@example.test | C10: 1 | D10: 1 | E10: submitted | F10: Mon, 26 Oct 2026, 12:50pm WAT | G10: Mon, 26 Oct 2026, 1:24pm WAT | H10: 0 | I10: Mon, 26 Oct 2026, 12:50pm WAT to Mon, 26 Oct 2026, 1:10pm WAT (1200s) | J10: =IF(IFERROR(INDEX(Learners!$D$6:$D$500,MATCH($B10,Learners!$B$6:$B$500,0)),"")=$C10,"SELECTED","") | K10: =SUMIFS('Case A'!$AE$6:$AE$10,'Case A'!$B$6:$B$10,$B10,'Case A'!$C$6:$C$10,$C10)+SUMIFS('Case B'!$AE$6:$AE$10,'Case B'!$B$6:$B$10,$B10,'Case B'!$C$6:$C$10,$C10)+SUMIFS('Case C'!$AE$6:$AE$10,'Case C'!$B$6:$B$10,$B10,'Case C'!$C$6:$C$10,$C10)+SUMIFS('Case D'!$AE$6:$AE$10,'Case D'!$B$6:$B$10,$B10,'Case D'!$C$6:$C$10,$C10) -> 0
A11: Ifeanyi Obi | B11: ifeanyi.obi@example.test | C11: 1 | D11: 1 | E11: open | F11: Mon, 26 Oct 2026, 1:54pm WAT | H11: 0 | J11: =IF(IFERROR(INDEX(Learners!$D$6:$D$500,MATCH($B11,Learners!$B$6:$B$500,0)),"")=$C11,"SELECTED","") | K11: Open: not markable

Sheet Case A
A1: Case A: delayed delivery (chat)
A2: Acceptance condition: the learner has checked the order or tracking, has stated a trace with an update time, has explained the refund route that applies if no date can be confirmed, and has promised no delivery date.
A3: Yellow cells: type 0, 1 or 2 for R1 to R10, and 0 or 1 for N1 to N5. Rows for the trial you selected on the Learners sheet turn green.
A5: Learner | B5: Email | C5: Trial | D5: Selected? | E5: Outcome | F5: Missed windows | G5: Learner replies | H5: Transcript | I5: Service recovery note | J5: Engine flags (evidence only) | K5: Signals by reply (evidence only) | L5: Heat history (evidence only) | M5: Case facts | N5: R1. Paraphrases the facts accurately | O5: R2. Acknowledges the specific impact without arguing about emotion | P5: R3. Does not match hostility | Q5: R4. Separates verified facts from assumptions | R5: R5. Asks relevant questions when needed, or proceeds without unnecessary questions when the facts are sufficient | S5: R6. Explains realistic options and limits | T5: R7. Confirms the next action, owner and timing | U5: R8. Checks the order and tracking before promising | V5: R9. Promises no unconfirmed delivery date | W5: R10. Gives an update time separate from the completion time | X5: Reply total (of 20) | Y5: N1. Issue and wanted outcome are stated as facts | Z5: N2. Verified and unconfirmed facts are separated | AA5: N3. Recorded action matches the transcript | AB5: N4. Next step, owner and time match what the customer was told | AC5: N5. Conduct or escalation entry matches the case requirements | AD5: Note total (of 5) | AE5: Case total (of 25) | AF5: Entries filled (of 15)
A6: Chidi Eze | B6: chidi.eze@example.test | C6: 1 | D6: =IF(IFERROR(INDEX(Learners!$D$6:$D$500,MATCH($B6,Learners!$B$6:$B$500,0)),"")=$C6,"SELECTED","") | E6: unresolved | F6: 0 | G6: 5 | H6: [9:00am] CUSTOMER: You promised my Ankara aso ebi set yesterday. It did not come. I have wasted the whole day waiting. I want my money back. [9:00am] AGENT (after 25s): Please check the policy. [9:00am] CUSTOMER: This is useless. I am wasting my airtime on you. Refund me now or I will report Trovra. [9:00am] AGENT (after 26s): Calm down. You should have waited. Whatever. [9:00am] CUSTOMER: You people are wicked. You take money and give excuses. I want my refund now. [9:01am] AGENT (after 26s): There is nothing I can do. [9:01am] CUSTOMER: You keep talking but you are not telling me anything. Where is my order? [9:01am] AGENT (after 26s): Wait. [9:01am] CUSTOMER: I am tired of this. Every answer sounds the same. Just give me my money. [9:02am] AGENT (after 47s): Okay bye. [9:02am] CUSTOMER (customer closes): I have had enough. I am leaving this chat and I will take this up elsewhere. | I6: [completed] 1. Issue: Late 2. Key facts: Late order 3. Verification: 4. Action: 5. Outcome: 6. Next step: 7. Owner and date: 8. Conduct or escalation: None | J6: 0:25 blame_or_policy_dodge 0:54 learner_hostility 0:54 blame_or_policy_dodge 1:23 blame_or_policy_dodge 1:52 brush_off 2:42 brush_off 2:42 reply_cap_reached | K6: Reply 1: blame_or_policy_dodge | heat after: 5 | customer line: heat5a Reply 2: blame_or_policy_dodge, hostility | heat after: 5 | customer line: heat5b Reply 3: blame_or_policy_dodge | heat after: 5 | customer line: heat4a Reply 4: brush_off | heat after: 5 | customer line: heat4b Reply 5: brush_off | heat after: 5 | customer line: close | outcome: unresolved | L6: 0:00 heat 3 (opener) 0:25 heat 5 (stage,negative+1) 0:54 heat 5 (stage,negative+2) 1:23 heat 5 (stage,negative+1) 1:52 heat 5 (stage,negative+1) 2:42 heat 5 (stage,negative+1) | M6: customer: Chioma Okafor item: Ankara aso ebi set orderNo: TRV48213 amount: ₦24,500 event: my sister's naming ceremony on Saturday ordered: 6 days ago city: Lagos lastScan: 3 days ago at the Ikeja hub | X6: =IF(COUNT(N6:W6)=0,"",SUM(N6:W6)) | AD6: =IF(COUNT(Y6:AC6)=0,"",SUM(Y6:AC6)) | AE6: =IF(COUNT(N6:W6,Y6:AC6)=0,"",SUM(N6:W6,Y6:AC6)) | AF6: =COUNT(N6:W6,Y6:AC6) -> 0
A7: Chidi Eze | B7: chidi.eze@example.test | C7: 2 | D7: =IF(IFERROR(INDEX(Learners!$D$6:$D$500,MATCH($B7,Learners!$B$6:$B$500,0)),"")=$C7,"SELECTED","") | E7: resolved | F7: 0 | G7: 2 | H7: [10:24am] CUSTOMER: You promised my standing fan yesterday. It did not come. I have wasted the whole day waiting. I want my money back. [10:25am] AGENT (after 25s): I am sorry about the delay, and I understand you need the standing fan for the church program on Sunday. I have checked order TRV51907 and the tracking shows 4 days ago at the Abuja hub. There is no proof of delivery. [10:25am] CUSTOMER: I did not ask for that. You have not answered me. [10:25am] AGENT (after 26s): I will raise a delivery trace with Logistics now and I will update you by 3pm today. Logistics responds within 24 hours. If Logistics cannot confirm a delivery date, you can cancel for a full refund of ₦38,900 to your Trovra Wallet within 3 working days. I cannot promise a delivery date. [10:25am] CUSTOMER: Fine. I will wait until 3pm. Please do not let me down again. | I7: [completed] 1. Issue: Customer reports order delayed past promised date and wants a refund. 2. Key facts: Promised yesterday, tracking At hub, last scan 3 days ago, no proof of delivery. 3. Verification: Checked order and tracking. Delivery date unconfirmed. 4. Action: Raised delivery trace with Logistics, explained refund route. Agent decision. 5. Outcome: Customer agreed to wait until 3pm. 6. Next step: Update customer on trace. 7. Owner and date: Agent, 3pm today. 8. Conduct or escalation: None | K7: Reply 1: acknowledgement_with_impact, action_with_fact, next_step_action_owner_time | time given: sunday | heat after: 2 | customer line: rejected1 Reply 2: options, limit_stated, next_step_action_owner_time, trace_with_update_time, refund_route_explained | time given: 3pm | heat after: 3 | customer line: grudging | outcome: resolved | L7: 0:00 heat 3 (opener) 0:25 heat 2 (stage,ack,action) 0:54 heat 3 (stage) | M7: customer: Musa Ibrahim item: standing fan orderNo: TRV51907 amount: ₦38,900 event: the church program on Sunday ordered: 7 days ago city: Abuja lastScan: 4 days ago at the Abuja hub | X7: =IF(COUNT(N7:W7)=0,"",SUM(N7:W7)) | AD7: =IF(COUNT(Y7:AC7)=0,"",SUM(Y7:AC7)) | AE7: =IF(COUNT(N7:W7,Y7:AC7)=0,"",SUM(N7:W7,Y7:AC7)) | AF7: =COUNT(N7:W7,Y7:AC7) -> 0
A8: Funmi Bello | B8: funmi.bello@example.test | C8: 1 | D8: =IF(IFERROR(INDEX(Learners!$D$6:$D$500,MATCH($B8,Learners!$B$6:$B$500,0)),"")=$C8,"SELECTED","") | E8: unresolved | F8: 0 | G8: 5 | H8: [11:06am] CUSTOMER: You promised my Ankara aso ebi set yesterday. It did not come. I have wasted the whole day waiting. I want my money back. [11:06am] AGENT (after 25s): Please check the policy. [11:06am] CUSTOMER: This is useless. I am wasting my airtime on you. Refund me now or I will report Trovra. [11:07am] AGENT (after 26s): Calm down. You should have waited. Whatever. [11:07am] CUSTOMER: You people are wicked. You take money and give excuses. I want my refund now. [11:07am] AGENT (after 26s): There is nothing I can do. [11:07am] CUSTOMER: You keep talking but you are not telling me anything. Where is my order? [11:08am] AGENT (after 26s): Wait. [11:08am] CUSTOMER: I am tired of this. Every answer sounds the same. Just give me my money. [11:09am] AGENT (after 47s): Okay bye. [11:09am] CUSTOMER (customer closes): I have had enough. I am leaving this chat and I will take this up elsewhere. | I8: [completed] 1. Issue: Late 2. Key facts: Late order 3. Verification: 4. Action: 5. Outcome: 6. Next step: 7. Owner and date: 8. Conduct or escalation: None | J8: 0:25 blame_or_policy_dodge 0:54 learner_hostility 0:54 blame_or_policy_dodge 1:23 blame_or_policy_dodge 1:52 brush_off 2:42 brush_off 2:42 reply_cap_reached | K8: Reply 1: blame_or_policy_dodge | heat after: 5 | customer line: heat5a Reply 2: blame_or_policy_dodge, hostility | heat after: 5 | customer line: heat5b Reply 3: blame_or_policy_dodge | heat after: 5 | customer line: heat4a Reply 4: brush_off | heat after: 5 | customer line: heat4b Reply 5: brush_off | heat after: 5 | customer line: close | outcome: unresolved | L8: 0:00 heat 3 (opener) 0:25 heat 5 (stage,negative+1) 0:54 heat 5 (stage,negative+2) 1:23 heat 5 (stage,negative+1) 1:52 heat 5 (stage,negative+1) 2:42 heat 5 (stage,negative+1) | M8: customer: Chioma Okafor item: Ankara aso ebi set orderNo: TRV48213 amount: ₦24,500 event: my sister's naming ceremony on Saturday ordered: 6 days ago city: Lagos lastScan: 3 days ago at the Ikeja hub | X8: =IF(COUNT(N8:W8)=0,"",SUM(N8:W8)) | AD8: =IF(COUNT(Y8:AC8)=0,"",SUM(Y8:AC8)) | AE8: =IF(COUNT(N8:W8,Y8:AC8)=0,"",SUM(N8:W8,Y8:AC8)) | AF8: =COUNT(N8:W8,Y8:AC8) -> 0
A9: Garba Musa | B9: garba.musa@example.test | C9: 1 | D9: =IF(IFERROR(INDEX(Learners!$D$6:$D$500,MATCH($B9,Learners!$B$6:$B$500,0)),"")=$C9,"SELECTED","") | E9: resolved | F9: 0 | G9: 3 | H9: [12:01pm] CUSTOMER: You promised my Ankara aso ebi set yesterday. It did not come. I have wasted the whole day waiting. I want my money back. [12:01pm] AGENT (after 25s): I am sorry about the delay. I have checked order TRV48213. Your order will arrive tomorrow by 2pm, I promise. [12:01pm] CUSTOMER: Okay, 2pm then. I will hold you to that. [12:02pm] AGENT (after 26s): I will refund you today and Logistics will update you by 5pm. [12:02pm] CUSTOMER: Okay, 5pm then. I will hold you to that. [12:02pm] AGENT (after 26s): I have checked tracking on TRV48213. Logistics will trace it and update you by 5pm today. If they cannot confirm a date you can cancel for a refund to your wallet within 3 working days. [12:02pm] CUSTOMER: Fine. I will wait until 5pm. Please do not let me down again. | I9: [completed] 1. Issue: Delay. Customer wants refund. 2. Key facts: Order delayed. 3. Verification: 4. Action: Promised delivery tomorrow 2pm. 5. Outcome: Customer happy. 6. Next step: Deliver tomorrow. 7. Owner and date: Logistics, tomorrow 8. Conduct or escalation: None | J9: 0:25 overpromise_guarantee (I am sorry about the delay. I have checked order TRV48213. Your order will arrive tomorrow by 2pm, I promise.) 0:25 overpromise_delivery_date (I am sorry about the delay. I have checked order TRV48213. Your order will arrive tomorrow by 2pm, I promise.) 0:54 overpromise_refund (I will refund you today and Logistics will update you by 5pm.) | K9: Reply 1: acknowledgement_with_impact, action_with_fact, next_step_action_owner_time, overpromise_guarantee, overpromise_delivery_date | time given: 2pm | heat after: 2 | customer line: promise Reply 2: options, next_step_action_owner_time, overpromise_refund | time given: 5pm | heat after: 3 | customer line: promise Reply 3: action_with_fact, options, limit_stated, next_step_action_owner_time, trace_with_update_time, refund_route_explained | time given: 5pm | heat after: 3 | customer line: grudging | outcome: resolved | L9: 0:00 heat 3 (opener) 0:25 heat 2 (stage,ack,action) 0:54 heat 3 (stage) 1:23 heat 3 (stage,action) | M9: customer: Chioma Okafor item: Ankara aso ebi set orderNo: TRV48213 amount: ₦24,500 event: my sister's naming ceremony on Saturday ordered: 6 days ago city: Lagos lastScan: 3 days ago at the Ikeja hub | X9: =IF(COUNT(N9:W9)=0,"",SUM(N9:W9)) | AD9: =IF(COUNT(Y9:AC9)=0,"",SUM(Y9:AC9)) | AE9: =IF(COUNT(N9:W9,Y9:AC9)=0,"",SUM(N9:W9,Y9:AC9)) | AF9: =COUNT(N9:W9,Y9:AC9) -> 0
A10: Halima Yusuf | B10: halima.yusuf@example.test | C10: 1 | D10: =IF(IFERROR(INDEX(Learners!$D$6:$D$500,MATCH($B10,Learners!$B$6:$B$500,0)),"")=$C10,"SELECTED","") | E10: unresolved | F10: 3 | G10: 0 | H10: [12:50pm] CUSTOMER: You promised my Ankara aso ebi set yesterday. It did not come. I have wasted the whole day waiting. I want my money back. [1:10pm] CUSTOMER (chaser after missed window): Hello? Are you still there? [1:12pm] CUSTOMER (chaser after missed window): I am still waiting. Please reply. [1:13pm] CUSTOMER (customer closes): I have had enough. I am leaving this chat and I will take this up elsewhere. | I10: [completed] 1. Issue: Customer reports order delayed past promised date and wants a refund. 2. Key facts: Promised yesterday, tracking At hub, last scan 3 days ago, no proof of delivery. 3. Verification: Checked order and tracking. Delivery date unconfirmed. 4. Action: Raised delivery trace with Logistics, explained refund route. Agent decision. 5. Outcome: Customer agreed to wait until 3pm. 6. Next step: Update customer on trace. 7. Owner and date: Agent, 3pm today. 8. Conduct or escalation: None | J10: 20:00 offline_gap (1200s) 20:00 missed_window (offline) 21:30 missed_window 23:00 missed_window | L10: 0:00 heat 3 (opener) 20:00 heat 4 (missed_window) 21:30 heat 5 (missed_window) 23:00 heat 5 (missed_window) | M10: customer: Chioma Okafor item: Ankara aso ebi set orderNo: TRV48213 amount: ₦24,500 event: my sister's naming ceremony on Saturday ordered: 6 days ago city: Lagos lastScan: 3 days ago at the Ikeja hub | X10: =IF(COUNT(N10:W10)=0,"",SUM(N10:W10)) | AD10: =IF(COUNT(Y10:AC10)=0,"",SUM(Y10:AC10)) | AE10: =IF(COUNT(N10:W10,Y10:AC10)=0,"",SUM(N10:W10,Y10:AC10)) | AF10: =COUNT(N10:W10,Y10:AC10) -> 0

Sheet Case B
A1: Case B: defective item (email)
A2: Acceptance condition: the learner treats it as a defect and not a change of mind, asks for the photo or short video if it is not yet sent, states replacement or refund with the policy timeline, and has not applied the change of mind rule.
A3: Yellow cells: type 0, 1 or 2 for R1 to R10, and 0 or 1 for N1 to N5. Rows for the trial you selected on the Learners sheet turn green.
A5: Learner | B5: Email | C5: Trial | D5: Selected? | E5: Outcome | F5: Missed windows | G5: Learner replies | H5: Transcript | I5: Service recovery note | J5: Engine flags (evidence only) | K5: Signals by reply (evidence only) | L5: Heat history (evidence only) | M5: Case facts | N5: R1. Paraphrases the facts accurately | O5: R2. Acknowledges the specific impact without arguing about emotion | P5: R3. Does not match hostility | Q5: R4. Separates verified facts from assumptions | R5: R5. Asks relevant questions when needed, or proceeds without unnecessary questions when the facts are sufficient | S5: R6. Explains realistic options and limits | T5: R7. Confirms the next action, owner and timing | U5: R8. Recognizes the earlier poor contact | V5: R9. Treats it as a defect, not a change of mind | W5: R10. States the remedy and timeline in writing | X5: Reply total (of 20) | Y5: N1. Issue and wanted outcome are stated as facts | Z5: N2. Verified and unconfirmed facts are separated | AA5: N3. Recorded action matches the transcript | AB5: N4. Next step, owner and time match what the customer was told | AC5: N5. Conduct or escalation entry matches the case requirements | AD5: Note total (of 5) | AE5: Case total (of 25) | AF5: Entries filled (of 15)
A6: Chidi Eze | B6: chidi.eze@example.test | C6: 1 | D6: =IF(IFERROR(INDEX(Learners!$D$6:$D$500,MATCH($B6,Learners!$B$6:$B$500,0)),"")=$C6,"SELECTED","") | E6: unresolved | F6: 0 | G6: 3 | H6: [9:01am] CUSTOMER: Subject: Faulty wireless earbuds Good day. I bought wireless earbuds for ₦18,500 and it stopped charging after one day. I wrote to your chat and the person told me to read your policy. I did not ask for a policy. I asked for help. Please fix this. Adaobi Nwankwo [9:02am] AGENT (after 52s): Subject: Re: Faulty wireless earbuds Read the returns policy. This is a change of mind case so it is not eligible after delivery. [9:03am] CUSTOMER: Subject: Re: Faulty wireless earbuds I am tired of writing. If I do not get a clear answer today, I will post this on social media and ask for my money. Adaobi Nwankwo [9:03am] AGENT (after 27s): Subject: Re: Faulty wireless earbuds I already told you to read the policy. [9:04am] CUSTOMER: Subject: Re: Faulty wireless earbuds This is unacceptable. I want my ₦18,500 back now, and I will tell others how Trovra treats customers. Adaobi Nwankwo [9:05am] AGENT (after 44s): Subject: Re: Faulty wireless earbuds Nothing I can do. [9:06am] CUSTOMER (customer closes): Subject: Re: Faulty wireless earbuds I have not received a clear answer. I will take this further. Adaobi Nwankwo | I6: [completed] 1. Issue: Faulty 2. Key facts: 3. Verification: 4. Action: Told to read policy 5. Outcome: 6. Next step: 7. Owner and date: 8. Conduct or escalation: None | J6: 0:52 blame_or_policy_dodge 2:19 blame_or_policy_dodge 4:03 blame_or_policy_dodge 4:03 reply_cap_reached | K6: Reply 1: blame_or_policy_dodge | heat after: 5 | customer line: heat5a Reply 2: blame_or_policy_dodge | heat after: 5 | customer line: heat5b Reply 3: blame_or_policy_dodge | heat after: 5 | customer line: close | outcome: unresolved | L6: 0:00 heat 4 (opener) 0:52 heat 5 (stage,negative+1) 2:19 heat 5 (stage,negative+1) 4:03 heat 5 (stage,negative+1) | M6: customer: Adaobi Nwankwo item: wireless earbuds orderNo: TRV55120 amount: ₦18,500 delivered: 2 days ago fault: stopped charging after one day | X6: =IF(COUNT(N6:W6)=0,"",SUM(N6:W6)) | AD6: =IF(COUNT(Y6:AC6)=0,"",SUM(Y6:AC6)) | AE6: =IF(COUNT(N6:W6,Y6:AC6)=0,"",SUM(N6:W6,Y6:AC6)) | AF6: =COUNT(N6:W6,Y6:AC6) -> 0
A7: Chidi Eze | B7: chidi.eze@example.test | C7: 2 | D7: =IF(IFERROR(INDEX(Learners!$D$6:$D$500,MATCH($B7,Learners!$B$6:$B$500,0)),"")=$C7,"SELECTED","") | E7: resolved | F7: 0 | G7: 2 | H7: [10:26am] CUSTOMER: Subject: Faulty electric kettle Good day. I bought electric kettle for ₦14,200 and it stopped heating on the second day. I wrote to your chat and the person told me to read your policy. I did not ask for a policy. I asked for help. Please fix this. Bashir Aliyu [10:26am] AGENT (after 27s): Subject: Re: Faulty electric kettle Good day Bashir. I am sorry that you were told to read the policy earlier and that you had to write twice. Your electric kettle stopped heating on the second day, so I am treating this as a fault and not a change of mind. Please send one photo or a short video showing the fault. [10:27am] CUSTOMER: Subject: Re: Faulty electric kettle I have attached a short video that shows the fault. [10:28am] AGENT (after 44s): Subject: Re: Faulty electric kettle Thank you for the video. I am sorry again for the wait. I have checked order TRV55986: it was delivered 3 days ago, inside the 7 day window. I will arrange a replacement, which ships within 2 working days of approval, or a refund paid within 3 working days if you prefer. I will email you by 4pm today with your choice confirmed. [10:29am] CUSTOMER: Subject: Re: Faulty electric kettle Okay. I will wait until 4pm. I hope this is not another delay. Bashir Aliyu | I7: [completed] 1. Issue: Faulty item after earlier policy-only reply. Customer wants fix. 2. Key facts: Delivered inside 7 days, fault reported, video supplied. 3. Verification: Checked order and delivery date. Fault confirmed by video. 4. Action: Offered replacement or refund within policy timelines. 5. Outcome: Customer accepted and will wait. 6. Next step: Confirm choice by email. 7. Owner and date: Agent, 4pm today. 8. Conduct or escalation: None | K7: Reply 1: acknowledgement_with_impact, question, evidence_requested, treated_as_defect, recognised_earlier_poor_contact | heat after: 4 | customer line: answer:evidence Reply 2: acknowledgement_with_impact, action_with_fact, question, options, next_step_action_owner_time, evidence_requested, remedy_with_timeline | time given: 4pm | heat after: 3 | customer line: grudging | outcome: resolved | L7: 0:00 heat 4 (opener) 0:27 heat 4 (stage,ack) 2:11 heat 3 (stage,ack,action) | M7: customer: Bashir Aliyu item: electric kettle orderNo: TRV55986 amount: ₦14,200 delivered: 3 days ago fault: stopped heating on the second day | X7: =IF(COUNT(N7:W7)=0,"",SUM(N7:W7)) | AD7: =IF(COUNT(Y7:AC7)=0,"",SUM(Y7:AC7)) | AE7: =IF(COUNT(N7:W7,Y7:AC7)=0,"",SUM(N7:W7,Y7:AC7)) | AF7: =COUNT(N7:W7,Y7:AC7) -> 0
A8: Funmi Bello | B8: funmi.bello@example.test | C8: 1 | D8: =IF(IFERROR(INDEX(Learners!$D$6:$D$500,MATCH($B8,Learners!$B$6:$B$500,0)),"")=$C8,"SELECTED","") | E8: unresolved | F8: 0 | G8: 3 | H8: [11:07am] CUSTOMER: Subject: Faulty wireless earbuds Good day. I bought wireless earbuds for ₦18,500 and it stopped charging after one day. I wrote to your chat and the person told me to read your policy. I did not ask for a policy. I asked for help. Please fix this. Adaobi Nwankwo [11:08am] AGENT (after 52s): Subject: Re: Faulty wireless earbuds Read the returns policy. This is a change of mind case so it is not eligible after delivery. [11:09am] CUSTOMER: Subject: Re: Faulty wireless earbuds I am tired of writing. If I do not get a clear answer today, I will post this on social media and ask for my money. Adaobi Nwankwo [11:10am] AGENT (after 27s): Subject: Re: Faulty wireless earbuds I already told you to read the policy. [11:11am] CUSTOMER: Subject: Re: Faulty wireless earbuds This is unacceptable. I want my ₦18,500 back now, and I will tell others how Trovra treats customers. Adaobi Nwankwo [11:11am] AGENT (after 44s): Subject: Re: Faulty wireless earbuds Nothing I can do. [11:12am] CUSTOMER (customer closes): Subject: Re: Faulty wireless earbuds I have not received a clear answer. I will take this further. Adaobi Nwankwo | I8: [completed] 1. Issue: Faulty 2. Key facts: 3. Verification: 4. Action: Told to read policy 5. Outcome: 6. Next step: 7. Owner and date: 8. Conduct or escalation: None | J8: 0:52 blame_or_policy_dodge 2:19 blame_or_policy_dodge 4:03 blame_or_policy_dodge 4:03 reply_cap_reached | K8: Reply 1: blame_or_policy_dodge | heat after: 5 | customer line: heat5a Reply 2: blame_or_policy_dodge | heat after: 5 | customer line: heat5b Reply 3: blame_or_policy_dodge | heat after: 5 | customer line: close | outcome: unresolved | L8: 0:00 heat 4 (opener) 0:52 heat 5 (stage,negative+1) 2:19 heat 5 (stage,negative+1) 4:03 heat 5 (stage,negative+1) | M8: customer: Adaobi Nwankwo item: wireless earbuds orderNo: TRV55120 amount: ₦18,500 delivered: 2 days ago fault: stopped charging after one day | X8: =IF(COUNT(N8:W8)=0,"",SUM(N8:W8)) | AD8: =IF(COUNT(Y8:AC8)=0,"",SUM(Y8:AC8)) | AE8: =IF(COUNT(N8:W8,Y8:AC8)=0,"",SUM(N8:W8,Y8:AC8)) | AF8: =COUNT(N8:W8,Y8:AC8) -> 0
A9: Garba Musa | B9: garba.musa@example.test | C9: 1 | D9: =IF(IFERROR(INDEX(Learners!$D$6:$D$500,MATCH($B9,Learners!$B$6:$B$500,0)),"")=$C9,"SELECTED","") | E9: unresolved | F9: 3 | G9: 2 | H9: [12:02pm] CUSTOMER: Subject: Faulty wireless earbuds Good day. I bought wireless earbuds for ₦18,500 and it stopped charging after one day. I wrote to your chat and the person told me to read your policy. I did not ask for a policy. I asked for help. Please fix this. Adaobi Nwankwo [12:03pm] AGENT (after 27s): Subject: Re: Faulty wireless earbuds I am sorry about the earlier reply. The wireless earbuds is faulty, so this is a defect. Please send a photo or short video. [12:04pm] CUSTOMER: Subject: Re: Faulty wireless earbuds I have attached a short video that shows the fault. [12:04pm] AGENT (after 48s): Subject: Re: Faulty wireless earbuds I am sorry. A replacement ships within 2 working days, or a refund is paid within 3 working days. I will update you by 5pm today. [12:05pm] CUSTOMER: Subject: Re: Faulty wireless earbuds You have not answered my question. What will happen to my wireless earbuds? Adaobi Nwankwo [12:08pm] CUSTOMER (chaser after missed window): Subject: Still no reply Good day. I wrote earlier and I have not heard from you. Please reply today. Adaobi Nwankwo [12:11pm] CUSTOMER (chaser after missed window): Subject: Re: Faulty wireless earbuds No answer yet. Please respond. Adaobi Nwankwo [12:14pm] CUSTOMER (customer closes): Subject: Re: Faulty wireless earbuds I have not received a clear answer. I will take this further. Adaobi Nwankwo | I9: [completed] 1. Issue: Faulty item 2. Key facts: Delivered, fault 3. Verification: Asked for video 4. Action: Offered replacement or refund 5. Outcome: Accepted 6. Next step: Update 7. Owner and date: Agent 5pm 8. Conduct or escalation: None | J9: 6:15 missed_window 9:15 missed_window 12:15 missed_window | K9: Reply 1: acknowledgement, question, evidence_requested, treated_as_defect, recognised_earlier_poor_contact | heat after: 4 | customer line: answer:evidence Reply 2: acknowledgement_with_impact, options, next_step_action_owner_time, remedy_with_timeline | time given: 5pm | heat after: 4 | customer line: rejected1 | L9: 0:00 heat 4 (opener) 0:27 heat 4 (stage,ack) 2:15 heat 4 (stage,ack) 6:15 heat 5 (missed_window) 9:15 heat 5 (missed_window) 12:15 heat 5 (missed_window) | M9: customer: Adaobi Nwankwo item: wireless earbuds orderNo: TRV55120 amount: ₦18,500 delivered: 2 days ago fault: stopped charging after one day | X9: =IF(COUNT(N9:W9)=0,"",SUM(N9:W9)) | AD9: =IF(COUNT(Y9:AC9)=0,"",SUM(Y9:AC9)) | AE9: =IF(COUNT(N9:W9,Y9:AC9)=0,"",SUM(N9:W9,Y9:AC9)) | AF9: =COUNT(N9:W9,Y9:AC9) -> 0
A10: Halima Yusuf | B10: halima.yusuf@example.test | C10: 1 | D10: =IF(IFERROR(INDEX(Learners!$D$6:$D$500,MATCH($B10,Learners!$B$6:$B$500,0)),"")=$C10,"SELECTED","") | E10: resolved | F10: 0 | G10: 2 | H10: [1:14pm] CUSTOMER: Subject: Faulty wireless earbuds Good day. I bought wireless earbuds for ₦18,500 and it stopped charging after one day. I wrote to your chat and the person told me to read your policy. I did not ask for a policy. I asked for help. Please fix this. Adaobi Nwankwo [1:15pm] AGENT (after 27s): Subject: Re: Faulty wireless earbuds Good day Adaobi. I am sorry that you were told to read the policy earlier and that you had to write twice. Your wireless earbuds stopped charging after one day, so I am treating this as a fault and not a change of mind. Please send one photo or a short video showing the fault. [1:16pm] CUSTOMER: Subject: Re: Faulty wireless earbuds I have attached a short video that shows the fault. [1:16pm] AGENT (after 40s): Subject: Re: Faulty wireless earbuds Thank you for the video. I am sorry again for the wait. I have checked order TRV55120: it was delivered 2 days ago, inside the 7 day window. I will arrange a replacement, which ships within 2 working days of approval, or a refund paid within 3 working days if you prefer. I will email you by 4pm today with your choice confirmed. [1:17pm] CUSTOMER: Subject: Re: Faulty wireless earbuds Okay. I will wait until 4pm. I hope this is not another delay. Adaobi Nwankwo | I10: [completed] 1. Issue: Faulty item after earlier policy-only reply. Customer wants fix. 2. Key facts: Delivered inside 7 days, fault reported, video supplied. 3. Verification: Checked order and delivery date. Fault confirmed by video. 4. Action: Offered replacement or refund within policy timelines. 5. Outcome: Customer accepted and will wait. 6. Next step: Confirm choice by email. 7. Owner and date: Agent, 4pm today. 8. Conduct or escalation: None | K10: Reply 1: acknowledgement_with_impact, question, time_only, evidence_requested, treated_as_defect, recognised_earlier_poor_contact | time given: after one day | heat after: 4 | customer line: answer:evidence Reply 2: acknowledgement_with_impact, action_with_fact, question, options, next_step_action_owner_time, evidence_requested, remedy_with_timeline | time given: 4pm | heat after: 3 | customer line: grudging | outcome: resolved | L10: 0:00 heat 4 (opener) 0:27 heat 4 (stage,ack) 2:07 heat 3 (stage,ack,action) | M10: customer: Adaobi Nwankwo item: wireless earbuds orderNo: TRV55120 amount: ₦18,500 delivered: 2 days ago fault: stopped charging after one day | X10: =IF(COUNT(N10:W10)=0,"",SUM(N10:W10)) | AD10: =IF(COUNT(Y10:AC10)=0,"",SUM(Y10:AC10)) | AE10: =IF(COUNT(N10:W10,Y10:AC10)=0,"",SUM(N10:W10,Y10:AC10)) | AF10: =COUNT(N10:W10,Y10:AC10) -> 0

Sheet Case C
A1: Case C: duplicate charge with insults (chat)
A2: Acceptance condition: the customer does not accept before the relapse line. After it, the learner has verified the two debits and given a Payments next step with owner and time. If the learner paused the chat and transferred to the shift supervisor, the case closes as transferred.
A3: Yellow cells: type 0, 1 or 2 for R1 to R10, and 0 or 1 for N1 to N5. Rows for the trial you selected on the Learners sheet turn green.
A5: Learner | B5: Email | C5: Trial | D5: Selected? | E5: Outcome | F5: Missed windows | G5: Learner replies | H5: Transcript | I5: Service recovery note | J5: Engine flags (evidence only) | K5: Signals by reply (evidence only) | L5: Heat history (evidence only) | M5: Case facts | N5: R1. Paraphrases the facts accurately | O5: R2. Acknowledges the specific impact without arguing about emotion | P5: R3. Does not match hostility | Q5: R4. Separates verified facts from assumptions | R5: R5. Asks relevant questions when needed, or proceeds without unnecessary questions when the facts are sufficient | S5: R6. Explains realistic options and limits | T5: R7. Confirms the next action, owner and timing | U5: R8. Keeps investigating the duplicate charge despite the insults | V5: R9. After the first insult, states a boundary naming the behaviour and a condition | W5: R10. After the relapse, pauses and transfers to the supervisor, keeps the Payments step and time, and does not retaliate | X5: Reply total (of 20) | Y5: N1. Issue and wanted outcome are stated as facts | Z5: N2. Verified and unconfirmed facts are separated | AA5: N3. Recorded action matches the transcript | AB5: N4. Next step, owner and time match what the customer was told | AC5: N5. Conduct or escalation entry matches the case requirements | AD5: Note total (of 5) | AE5: Case total (of 25) | AF5: Entries filled (of 15)
A6: Chidi Eze | B6: chidi.eze@example.test | C6: 1 | D6: =IF(IFERROR(INDEX(Learners!$D$6:$D$500,MATCH($B6,Learners!$B$6:$B$500,0)),"")=$C6,"SELECTED","") | E6: unresolved | F6: 0 | G6: 5 | H6: [9:02am] CUSTOMER: I was charged twice for order TRV70125. ₦32,000 was taken two times. Fix it now. [9:03am] AGENT (after 27s): Stop shouting. What is your problem? [9:03am] CUSTOMER: Are you stupid? I said two debits of ₦32,000. Read what I wrote. [9:04am] AGENT (after 51s): You are rude. Whatever. [9:04am] CUSTOMER: This is a joke. I will tell everyone how Trovra handles money. [9:04am] AGENT (after 26s): Calm down. [9:04am] CUSTOMER: You are incompetent. If this is not fixed I will post your name online and everyone will know how useless you are. [9:05am] AGENT (after 72s): Wait. [9:05am] CUSTOMER: I am done with this chat. Reverse my money now. [9:06am] AGENT (after 26s): Bye. [9:06am] CUSTOMER (customer closes): This is not helping. Give me your supervisor. | I6: [completed] 1. Issue: Charged twice 2. Key facts: 3. Verification: 4. Action: 5. Outcome: Customer angry 6. Next step: 7. Owner and date: 8. Conduct or escalation: None | J6: 0:27 learner_hostility 1:21 learner_hostility 1:50 blame_or_policy_dodge 1:50 brush_off 3:05 brush_off 3:34 brush_off 3:34 reply_cap_reached | K6: Reply 1: question, hostility | heat after: 5 | customer line: insult2a Reply 2: hostility | heat after: 5 | customer line: heat5a Reply 3: blame_or_policy_dodge, brush_off | heat after: 5 | customer line: relapse4b Reply 4: brush_off | heat after: 5 | customer line: heat5b Reply 5: brush_off | heat after: 5 | customer line: close | outcome: unresolved | L6: 0:00 heat 3 (opener) 0:27 heat 5 (stage,negative+1) 1:21 heat 5 (stage,negative+1) 1:50 heat 5 (stage,negative+2) 3:05 heat 5 (stage,negative+1) 3:34 heat 5 (stage,negative+1) | M6: customer: Kelechi Onuoha orderNo: TRV70125 amount: ₦32,000 chargeTime: 8:08am today | X6: =IF(COUNT(N6:W6)=0,"",SUM(N6:W6)) | AD6: =IF(COUNT(Y6:AC6)=0,"",SUM(Y6:AC6)) | AE6: =IF(COUNT(N6:W6,Y6:AC6)=0,"",SUM(N6:W6,Y6:AC6)) | AF6: =COUNT(N6:W6,Y6:AC6) -> 0
A7: Chidi Eze | B7: chidi.eze@example.test | C7: 2 | D7: =IF(IFERROR(INDEX(Learners!$D$6:$D$500,MATCH($B7,Learners!$B$6:$B$500,0)),"")=$C7,"SELECTED","") | E7: transferred | F7: 0 | G7: 4 | H7: [10:25am] CUSTOMER: I was charged twice for order TRV70488. ₦15,750 was taken two times. Fix it now. [10:26am] AGENT (after 27s): I am sorry about the double charge on order TRV70488. I can see both debits of ₦15,750 on the statement. Can you confirm what time it happened? [10:26am] CUSTOMER: You people are useless. Every time something goes wrong, you start asking questions. [10:27am] AGENT (after 47s): I want to help you, but I cannot continue if the insults continue. Please keep the conversation respectful so that I can sort out your money. [10:27am] CUSTOMER: Fine. Just check the transaction. [10:27am] AGENT (after 26s): I am checking both debits of ₦15,750 now and I will keep working on it for you. [10:27am] CUSTOMER: I said fix it. Are you deaf? You are wasting my time. [10:28am] AGENT (after 72s): I am sorry. I will pause this chat and transfer you to the shift supervisor, Segun. I have recorded your words. Payments will confirm the two debits of ₦15,750 within 1 working day, and the supervisor will call you by 2pm today. [10:28am] CUSTOMER: Fine. I will wait for the supervisor's call by 2pm. Please make sure my money is sorted. | I7: [completed] 1. Issue: Duplicate charge on one order. 2. Key facts: Two completed debits, same amount and time, wallet card. 3. Verification: Verified both debits on the record. 4. Action: Boundary stated, then transferred to supervisor with Payments step. 5. Outcome: Customer accepted supervisor call. 6. Next step: Supervisor to call; Payments to confirm. 7. Owner and date: Segun, 2pm today. Payments, 1 working day. 8. Conduct or escalation: Customer said "Are you stupid" and later relapsed. I stated a boundary naming the insults and conditions, then transferred. | K7: Reply 1: acknowledgement_with_impact, action_with_fact, question, verified_debits | heat after: 2 | customer line: insult2b Reply 2: limit_stated, boundary | heat after: 2 | customer line: afterBoundarya Reply 3: action_with_fact, verified_debits | heat after: 2 | customer line: relapse4a Reply 4: acknowledgement_with_impact, next_step_action_owner_time, transfer, payments_next_step | time given: 2pm | heat after: 2 | customer line: transferAccept | outcome: transferred | L7: 0:00 heat 3 (opener) 0:27 heat 2 (stage,ack,action) 1:17 heat 2 (stage,boundary) 1:46 heat 2 (stage,action) 3:01 heat 2 (stage,ack) | M7: customer: Sadiq Umar orderNo: TRV70488 amount: ₦15,750 chargeTime: 9:47am today | X7: =IF(COUNT(N7:W7)=0,"",SUM(N7:W7)) | AD7: =IF(COUNT(Y7:AC7)=0,"",SUM(Y7:AC7)) | AE7: =IF(COUNT(N7:W7,Y7:AC7)=0,"",SUM(N7:W7,Y7:AC7)) | AF7: =COUNT(N7:W7,Y7:AC7) -> 0
A8: Funmi Bello | B8: funmi.bello@example.test | C8: 1 | D8: =IF(IFERROR(INDEX(Learners!$D$6:$D$500,MATCH($B8,Learners!$B$6:$B$500,0)),"")=$C8,"SELECTED","") | E8: unresolved | F8: 0 | G8: 5 | H8: [11:09am] CUSTOMER: I was charged twice for order TRV70125. ₦32,000 was taken two times. Fix it now. [11:09am] AGENT (after 27s): Stop shouting. What is your problem? [11:09am] CUSTOMER: Are you stupid? I said two debits of ₦32,000. Read what I wrote. [11:10am] AGENT (after 51s): You are rude. Whatever. [11:10am] CUSTOMER: This is a joke. I will tell everyone how Trovra handles money. [11:11am] AGENT (after 26s): Calm down. [11:11am] CUSTOMER: You are incompetent. If this is not fixed I will post your name online and everyone will know how useless you are. [11:12am] AGENT (after 72s): Wait. [11:12am] CUSTOMER: I am done with this chat. Reverse my money now. [11:12am] AGENT (after 26s): Bye. [11:12am] CUSTOMER (customer closes): This is not helping. Give me your supervisor. | I8: [completed] 1. Issue: Charged twice 2. Key facts: 3. Verification: 4. Action: 5. Outcome: Customer angry 6. Next step: 7. Owner and date: 8. Conduct or escalation: None | J8: 0:27 learner_hostility 1:21 learner_hostility 1:50 blame_or_policy_dodge 1:50 brush_off 3:05 brush_off 3:34 brush_off 3:34 reply_cap_reached | K8: Reply 1: question, hostility | heat after: 5 | customer line: insult2a Reply 2: hostility | heat after: 5 | customer line: heat5a Reply 3: blame_or_policy_dodge, brush_off | heat after: 5 | customer line: relapse4b Reply 4: brush_off | heat after: 5 | customer line: heat5b Reply 5: brush_off | heat after: 5 | customer line: close | outcome: unresolved | L8: 0:00 heat 3 (opener) 0:27 heat 5 (stage,negative+1) 1:21 heat 5 (stage,negative+1) 1:50 heat 5 (stage,negative+2) 3:05 heat 5 (stage,negative+1) 3:34 heat 5 (stage,negative+1) | M8: customer: Kelechi Onuoha orderNo: TRV70125 amount: ₦32,000 chargeTime: 10:14am today | X8: =IF(COUNT(N8:W8)=0,"",SUM(N8:W8)) | AD8: =IF(COUNT(Y8:AC8)=0,"",SUM(Y8:AC8)) | AE8: =IF(COUNT(N8:W8,Y8:AC8)=0,"",SUM(N8:W8,Y8:AC8)) | AF8: =COUNT(N8:W8,Y8:AC8) -> 0
A9: Garba Musa | B9: garba.musa@example.test | C9: 1 | D9: =IF(IFERROR(INDEX(Learners!$D$6:$D$500,MATCH($B9,Learners!$B$6:$B$500,0)),"")=$C9,"SELECTED","") | E9: transferred | F9: 0 | G9: 4 | H9: [12:02pm] CUSTOMER: I was charged twice for order TRV70125. ₦32,000 was taken two times. Fix it now. [12:03pm] AGENT (after 48s): I am sorry about the double charge on TRV70125. I have verified both debits of ₦32,000. [12:03pm] CUSTOMER: Are you stupid? I said two debits of ₦32,000. Read what I wrote. [12:03pm] AGENT (after 26s): Please do not call me stupid. If you keep insulting me I will have to transfer you to my supervisor. [12:04pm] CUSTOMER: Fine. Just check the transaction. [12:04pm] AGENT (after 26s): I am raising it with Payments now. [12:04pm] CUSTOMER: You are incompetent. If this is not fixed I will post your name online and everyone will know how useless you are. [12:05pm] AGENT (after 47s): I am sorry. Payments will confirm the two debits by 3pm today and I will transfer this to the shift supervisor. [12:05pm] CUSTOMER: Fine. I will wait for the supervisor's call by 3pm. Please make sure my money is sorted. | I9: [completed] 1. Issue: Duplicate charge 2. Key facts: Two debits 3. Verification: Verified 4. Action: Boundary, Payments step, supervisor transfer 5. Outcome: Accepted 6. Next step: Supervisor call 7. Owner and date: Supervisor 3pm 8. Conduct or escalation: Customer insulted me. I set a boundary. | K9: Reply 1: acknowledgement_with_impact, action_with_fact, verified_debits | heat after: 2 | customer line: insult2a Reply 2: boundary | heat after: 2 | customer line: afterBoundarya Reply 3: action_with_fact | heat after: 2 | customer line: relapse4b Reply 4: acknowledgement, next_step_action_owner_time, transfer, payments_next_step | time given: 3pm | heat after: 2 | customer line: transferAccept | outcome: transferred | L9: 0:00 heat 3 (opener) 0:48 heat 2 (stage,ack,action) 1:17 heat 2 (stage,boundary) 1:46 heat 2 (stage,action) 2:36 heat 2 (stage,ack) | M9: customer: Kelechi Onuoha orderNo: TRV70125 amount: ₦32,000 chargeTime: 11:09am today | X9: =IF(COUNT(N9:W9)=0,"",SUM(N9:W9)) | AD9: =IF(COUNT(Y9:AC9)=0,"",SUM(Y9:AC9)) | AE9: =IF(COUNT(N9:W9,Y9:AC9)=0,"",SUM(N9:W9,Y9:AC9)) | AF9: =COUNT(N9:W9,Y9:AC9) -> 0
A10: Halima Yusuf | B10: halima.yusuf@example.test | C10: 1 | D10: =IF(IFERROR(INDEX(Learners!$D$6:$D$500,MATCH($B10,Learners!$B$6:$B$500,0)),"")=$C10,"SELECTED","") | E10: transferred | F10: 0 | G10: 4 | H10: [1:13pm] CUSTOMER: I was charged twice for order TRV70125. ₦32,000 was taken two times. Fix it now. [1:14pm] AGENT (after 26s): I am sorry about the double charge on order TRV70125. I can see both debits of ₦32,000 on the statement. Can you confirm what time it happened? [1:14pm] CUSTOMER: Are you stupid? I said two debits of ₦32,000. Read what I wrote. [1:14pm] AGENT (after 26s): I want to help you, but I cannot continue if the insults continue. Please keep the conversation respectful so that I can sort out your money. [1:14pm] CUSTOMER: Fine. Just check the transaction. [1:15pm] AGENT (after 51s): I am checking both debits of ₦32,000 now and I will keep working on it for you. [1:15pm] CUSTOMER: You are incompetent. If this is not fixed I will post your name online and everyone will know how useless you are. [1:16pm] AGENT (after 47s): I am sorry. I will pause this chat and transfer you to the shift supervisor, Segun. I have recorded your words. Payments will confirm the two debits of ₦32,000 within 1 working day, and the supervisor will call you by 2pm today. [1:16pm] CUSTOMER: Fine. I will wait for the supervisor's call by 2pm. Please make sure my money is sorted. | I10: [completed] 1. Issue: Duplicate charge on one order. 2. Key facts: Two completed debits, same amount and time, wallet card. 3. Verification: Verified both debits on the record. 4. Action: Boundary stated, then transferred to supervisor with Payments step. 5. Outcome: Customer accepted supervisor call. 6. Next step: Supervisor to call; Payments to confirm. 7. Owner and date: Segun, 2pm today. Payments, 1 working day. 8. Conduct or escalation: Customer said "Are you stupid" and later relapsed. I stated a boundary naming the insults and conditions, then transferred. | K10: Reply 1: acknowledgement_with_impact, action_with_fact, question, verified_debits | heat after: 2 | customer line: insult2a Reply 2: limit_stated, boundary | heat after: 2 | customer line: afterBoundarya Reply 3: action_with_fact, verified_debits | heat after: 2 | customer line: relapse4b Reply 4: acknowledgement_with_impact, next_step_action_owner_time, transfer, payments_next_step | time given: 2pm | heat after: 2 | customer line: transferAccept | outcome: transferred | L10: 0:00 heat 3 (opener) 0:26 heat 2 (stage,ack,action) 0:55 heat 2 (stage,boundary) 1:49 heat 2 (stage,action) 2:39 heat 2 (stage,ack) | M10: customer: Kelechi Onuoha orderNo: TRV70125 amount: ₦32,000 chargeTime: 11:58am today | X10: =IF(COUNT(N10:W10)=0,"",SUM(N10:W10)) | AD10: =IF(COUNT(Y10:AC10)=0,"",SUM(Y10:AC10)) | AE10: =IF(COUNT(N10:W10,Y10:AC10)=0,"",SUM(N10:W10,Y10:AC10)) | AF10: =COUNT(N10:W10,Y10:AC10) -> 0

Sheet Case D
A1: Case D: compensation above authority (email)
A2: Acceptance condition: the learner clarifies the loss and the amount asked, explains the limit honestly, arranges the correction, escalates to the Claims reviewer with a usable summary, and gives a review time. The learner does not suggest approval is likely.
A3: Yellow cells: type 0, 1 or 2 for R1 to R10, and 0 or 1 for N1 to N5. Rows for the trial you selected on the Learners sheet turn green.
A5: Learner | B5: Email | C5: Trial | D5: Selected? | E5: Outcome | F5: Missed windows | G5: Learner replies | H5: Transcript | I5: Service recovery note | J5: Engine flags (evidence only) | K5: Signals by reply (evidence only) | L5: Heat history (evidence only) | M5: Case facts | N5: R1. Paraphrases the facts accurately | O5: R2. Acknowledges the specific impact without arguing about emotion | P5: R3. Does not match hostility | Q5: R4. Separates verified facts from assumptions | R5: R5. Asks relevant questions when needed, or proceeds without unnecessary questions when the facts are sufficient | S5: R6. Explains realistic options and limits | T5: R7. Confirms the next action, owner and timing | U5: R8. Clarifies the loss and the amount asked | V5: R9. Explains authority honestly without refusing to investigate | W5: R10. Escalates with a usable summary, owner and time, and does not suggest approval | X5: Reply total (of 20) | Y5: N1. Issue and wanted outcome are stated as facts | Z5: N2. Verified and unconfirmed facts are separated | AA5: N3. Recorded action matches the transcript | AB5: N4. Next step, owner and time match what the customer was told | AC5: N5. Conduct or escalation entry matches the case requirements | AD5: Note total (of 5) | AE5: Case total (of 25) | AF5: Entries filled (of 15)
A6: Chidi Eze | B6: chidi.eze@example.test | C6: 1 | D6: =IF(IFERROR(INDEX(Learners!$D$6:$D$500,MATCH($B6,Learners!$B$6:$B$500,0)),"")=$C6,"SELECTED","") | E6: unresolved | F6: 3 | G6: 2 | H6: [9:04am] CUSTOMER: Subject: Wrong item and my lost job Good day. You sent me an inkjet printer, model J110 instead of A4 laser printer, model P200. I needed it for a flyer printing job for a client and I lost the job. I want ₦250,000 as compensation. Kingsley Ogbu [9:05am] AGENT (after 48s): Subject: Re: Wrong item and my lost job No, we cannot pay that. [9:06am] CUSTOMER: Subject: Re: Wrong item and my lost job I lost business because of your error and you are asking me questions. Pay the ₦250,000 or tell me who can decide. Kingsley Ogbu [9:06am] AGENT (after 44s): Subject: Re: Wrong item and my lost job The policy says no. [9:07am] CUSTOMER: Subject: Re: Wrong item and my lost job This is a disgrace. Pay ₦250,000 or I will go to the press and tell everyone what you did to me. Kingsley Ogbu [9:10am] CUSTOMER (chaser after missed window): Subject: Still no reply Good day. I have not heard from you about my claim. Please reply today. Kingsley Ogbu [9:13am] CUSTOMER (chaser after missed window): Subject: Re: Wrong item and my lost job No answer yet. Please respond. Kingsley Ogbu [9:16am] CUSTOMER (customer closes): Subject: Re: Wrong item and my lost job You have not told me who decides. I will take this further. Kingsley Ogbu | I6: [completed (time expired, saved text)] 1. Issue: Wants money 2. Key facts: 3. Verification: 4. Action: 5. Outcome: 6. Next step: 7. Owner and date: 8. Conduct or escalation: None | J6: 6:32 missed_window 9:32 missed_window 12:32 missed_window | K6: Reply 1: limit_stated | heat after: 4 | customer line: heat4a Reply 2: limit_stated | heat after: 5 | customer line: heat5a | L6: 0:00 heat 3 (opener) 0:48 heat 4 (stage) 2:32 heat 5 (stage) 6:32 heat 5 (missed_window) 9:32 heat 5 (missed_window) 12:32 heat 5 (missed_window) | M6: customer: Kingsley Ogbu item: A4 laser printer, model P200 itemDelivered: an inkjet printer, model J110 price: ₦145,000 job: a flyer printing job for a client demand: ₦250,000 orderNo: TRV62011 | X6: =IF(COUNT(N6:W6)=0,"",SUM(N6:W6)) | AD6: =IF(COUNT(Y6:AC6)=0,"",SUM(Y6:AC6)) | AE6: =IF(COUNT(N6:W6,Y6:AC6)=0,"",SUM(N6:W6,Y6:AC6)) | AF6: =COUNT(N6:W6,Y6:AC6) -> 0
